[2024-01-24T02:01:10.351+0800] {taskinstance.py:1090} INFO - Dependencies all met for dep_context=non-requeueable deps ti=<TaskInstance: youtube_comments_score.get_data manual__2024-01-23T17:42:39.428469+00:00 [queued]>
[2024-01-24T02:01:10.373+0800] {taskinstance.py:1090} INFO - Dependencies all met for dep_context=requeueable deps ti=<TaskInstance: youtube_comments_score.get_data manual__2024-01-23T17:42:39.428469+00:00 [queued]>
[2024-01-24T02:01:10.375+0800] {taskinstance.py:1288} INFO - 
--------------------------------------------------------------------------------
[2024-01-24T02:01:10.375+0800] {taskinstance.py:1289} INFO - Starting attempt 1 of 2
[2024-01-24T02:01:10.375+0800] {taskinstance.py:1290} INFO - 
--------------------------------------------------------------------------------
[2024-01-24T02:01:10.439+0800] {taskinstance.py:1309} INFO - Executing <Task(BashOperator): get_data> on 2024-01-23 17:42:39.428469+00:00
[2024-01-24T02:01:10.459+0800] {standard_task_runner.py:55} INFO - Started process 29624 to run task
[2024-01-24T02:01:10.463+0800] {standard_task_runner.py:82} INFO - Running: ['***', 'tasks', 'run', 'youtube_comments_score', 'get_data', 'manual__2024-01-23T17:42:39.428469+00:00', '--job-id', '6', '--raw', '--subdir', 'DAGS_FOLDER/youtube_comments_score.py', '--cfg-path', '/tmp/tmpajhq3y2j']
[2024-01-24T02:01:10.464+0800] {standard_task_runner.py:83} INFO - Job 6: Subtask get_data
[2024-01-24T02:01:10.804+0800] {task_command.py:389} INFO - Running <TaskInstance: youtube_comments_score.get_data manual__2024-01-23T17:42:39.428469+00:00 [running]> on host ml
[2024-01-24T02:01:11.059+0800] {taskinstance.py:1516} INFO - Exporting the following env vars:
AIRFLOW_CTX_DAG_OWNER=admin
AIRFLOW_CTX_DAG_ID=youtube_comments_score
AIRFLOW_CTX_TASK_ID=get_data
AIRFLOW_CTX_EXECUTION_DATE=2024-01-23T17:42:39.428469+00:00
AIRFLOW_CTX_TRY_NUMBER=1
AIRFLOW_CTX_DAG_RUN_ID=manual__2024-01-23T17:42:39.428469+00:00
[2024-01-24T02:01:11.062+0800] {subprocess.py:63} INFO - Tmp dir root location: 
 /tmp
[2024-01-24T02:01:11.063+0800] {subprocess.py:75} INFO - Running command: ['/usr/bin/bash', '-c', 'python3 /home/am/project/scripts/get_data.py']
[2024-01-24T02:01:11.092+0800] {subprocess.py:86} INFO - Output:
[2024-01-24T02:01:11.601+0800] {subprocess.py:93} INFO - Traceback (most recent call last):
[2024-01-24T02:01:11.601+0800] {subprocess.py:93} INFO -   File "/home/am/project/scripts/get_data.py", line 9, in <module>
[2024-01-24T02:01:11.602+0800] {subprocess.py:93} INFO -     video = api.search_by_keywords(q=query, search_type=["video"], count=10, limit=30)
[2024-01-24T02:01:11.602+0800] {subprocess.py:93} INFO -   File "/home/am/project/venv/lib/python3.10/site-packages/pyyoutube/api.py", line 1750, in search_by_keywords
[2024-01-24T02:01:11.602+0800] {subprocess.py:93} INFO -     return self.search(
[2024-01-24T02:01:11.602+0800] {subprocess.py:93} INFO -   File "/home/am/project/venv/lib/python3.10/site-packages/pyyoutube/api.py", line 1683, in search
[2024-01-24T02:01:11.602+0800] {subprocess.py:93} INFO -     res_data = self.paged_by_page_token(resource="search", args=args, count=count)
[2024-01-24T02:01:11.602+0800] {subprocess.py:93} INFO -   File "/home/am/project/venv/lib/python3.10/site-packages/pyyoutube/api.py", line 487, in paged_by_page_token
[2024-01-24T02:01:11.602+0800] {subprocess.py:93} INFO -     data = self._parse_response(resp)  # origin response
[2024-01-24T02:01:11.602+0800] {subprocess.py:93} INFO -   File "/home/am/project/venv/lib/python3.10/site-packages/pyyoutube/api.py", line 327, in _parse_response
[2024-01-24T02:01:11.602+0800] {subprocess.py:93} INFO -     raise PyYouTubeException(response)
[2024-01-24T02:01:11.602+0800] {subprocess.py:93} INFO - pyyoutube.error.PyYouTubeException: YouTubeException(status_code=403,message=YouTube Data API v3 has not been used in project 658100405976 before or it is disabled. Enable it by visiting https://console.developers.google.com/apis/api/youtube.googleapis.com/overview?project=658100405976 then retry. If you enabled this API recently, wait a few minutes for the action to propagate to our systems and retry.)
[2024-01-24T02:01:11.620+0800] {subprocess.py:97} INFO - Command exited with return code 1
[2024-01-24T02:01:11.823+0800] {taskinstance.py:1776} ERROR - Task failed with exception
Traceback (most recent call last):
  File "/home/am/project/venv/lib/python3.10/site-packages/airflow/operators/bash.py", line 196, in execute
    raise AirflowException(
airflow.exceptions.AirflowException: Bash command failed. The command returned a non-zero exit code 1.
[2024-01-24T02:01:11.856+0800] {taskinstance.py:1327} INFO - Marking task as UP_FOR_RETRY. dag_id=youtube_comments_score, task_id=get_data, execution_date=20240123T174239, start_date=20240123T180110, end_date=20240123T180111
[2024-01-24T02:01:11.895+0800] {standard_task_runner.py:100} ERROR - Failed to execute job 6 for task get_data (Bash command failed. The command returned a non-zero exit code 1.; 29624)
[2024-01-24T02:01:11.983+0800] {local_task_job.py:212} INFO - Task exited with return code 1
[2024-01-24T02:01:12.110+0800] {taskinstance.py:2596} INFO - 0 downstream tasks scheduled from follow-on schedule check
