[2024-01-24T02:00:57.025+0800] {taskinstance.py:1090} INFO - Dependencies all met for dep_context=non-requeueable deps ti=<TaskInstance: youtube_comments_score.get_data scheduled__2023-01-23T00:05:00+00:00 [queued]>
[2024-01-24T02:00:57.118+0800] {taskinstance.py:1090} INFO - Dependencies all met for dep_context=requeueable deps ti=<TaskInstance: youtube_comments_score.get_data scheduled__2023-01-23T00:05:00+00:00 [queued]>
[2024-01-24T02:00:57.119+0800] {taskinstance.py:1288} INFO - 
--------------------------------------------------------------------------------
[2024-01-24T02:00:57.119+0800] {taskinstance.py:1289} INFO - Starting attempt 2 of 2
[2024-01-24T02:00:57.119+0800] {taskinstance.py:1290} INFO - 
--------------------------------------------------------------------------------
[2024-01-24T02:00:57.148+0800] {taskinstance.py:1309} INFO - Executing <Task(BashOperator): get_data> on 2023-01-23 00:05:00+00:00
[2024-01-24T02:00:57.155+0800] {standard_task_runner.py:55} INFO - Started process 29467 to run task
[2024-01-24T02:00:57.170+0800] {standard_task_runner.py:82} INFO - Running: ['***', 'tasks', 'run', 'youtube_comments_score', 'get_data', 'scheduled__2023-01-23T00:05:00+00:00', '--job-id', '5', '--raw', '--subdir', 'DAGS_FOLDER/youtube_comments_score.py', '--cfg-path', '/tmp/tmp0aprwqim']
[2024-01-24T02:00:57.172+0800] {standard_task_runner.py:83} INFO - Job 5: Subtask get_data
[2024-01-24T02:00:57.672+0800] {task_command.py:389} INFO - Running <TaskInstance: youtube_comments_score.get_data scheduled__2023-01-23T00:05:00+00:00 [running]> on host ml
[2024-01-24T02:00:58.038+0800] {taskinstance.py:1516} INFO - Exporting the following env vars:
AIRFLOW_CTX_DAG_OWNER=admin
AIRFLOW_CTX_DAG_ID=youtube_comments_score
AIRFLOW_CTX_TASK_ID=get_data
AIRFLOW_CTX_EXECUTION_DATE=2023-01-23T00:05:00+00:00
AIRFLOW_CTX_TRY_NUMBER=2
AIRFLOW_CTX_DAG_RUN_ID=scheduled__2023-01-23T00:05:00+00:00
[2024-01-24T02:00:58.040+0800] {subprocess.py:63} INFO - Tmp dir root location: 
 /tmp
[2024-01-24T02:00:58.044+0800] {subprocess.py:75} INFO - Running command: ['/usr/bin/bash', '-c', 'python3 /home/am/project/scripts/get_data.py']
[2024-01-24T02:00:58.085+0800] {subprocess.py:86} INFO - Output:
[2024-01-24T02:00:58.980+0800] {subprocess.py:93} INFO - Traceback (most recent call last):
[2024-01-24T02:00:58.982+0800] {subprocess.py:93} INFO -   File "/home/am/project/scripts/get_data.py", line 9, in <module>
[2024-01-24T02:00:58.982+0800] {subprocess.py:93} INFO -     video = api.search_by_keywords(q=query, search_type=["video"], count=10, limit=30)
[2024-01-24T02:00:58.982+0800] {subprocess.py:93} INFO -   File "/home/am/project/venv/lib/python3.10/site-packages/pyyoutube/api.py", line 1750, in search_by_keywords
[2024-01-24T02:00:58.986+0800] {subprocess.py:93} INFO -     return self.search(
[2024-01-24T02:00:58.986+0800] {subprocess.py:93} INFO -   File "/home/am/project/venv/lib/python3.10/site-packages/pyyoutube/api.py", line 1683, in search
[2024-01-24T02:00:58.987+0800] {subprocess.py:93} INFO -     res_data = self.paged_by_page_token(resource="search", args=args, count=count)
[2024-01-24T02:00:58.987+0800] {subprocess.py:93} INFO -   File "/home/am/project/venv/lib/python3.10/site-packages/pyyoutube/api.py", line 487, in paged_by_page_token
[2024-01-24T02:00:58.996+0800] {subprocess.py:93} INFO -     data = self._parse_response(resp)  # origin response
[2024-01-24T02:00:58.997+0800] {subprocess.py:93} INFO -   File "/home/am/project/venv/lib/python3.10/site-packages/pyyoutube/api.py", line 327, in _parse_response
[2024-01-24T02:00:58.997+0800] {subprocess.py:93} INFO -     raise PyYouTubeException(response)
[2024-01-24T02:00:58.997+0800] {subprocess.py:93} INFO - pyyoutube.error.PyYouTubeException: YouTubeException(status_code=403,message=YouTube Data API v3 has not been used in project 658100405976 before or it is disabled. Enable it by visiting https://console.developers.google.com/apis/api/youtube.googleapis.com/overview?project=658100405976 then retry. If you enabled this API recently, wait a few minutes for the action to propagate to our systems and retry.)
[2024-01-24T02:00:59.113+0800] {subprocess.py:97} INFO - Command exited with return code 1
[2024-01-24T02:00:59.167+0800] {taskinstance.py:1776} ERROR - Task failed with exception
Traceback (most recent call last):
  File "/home/am/project/venv/lib/python3.10/site-packages/airflow/operators/bash.py", line 196, in execute
    raise AirflowException(
airflow.exceptions.AirflowException: Bash command failed. The command returned a non-zero exit code 1.
[2024-01-24T02:00:59.176+0800] {taskinstance.py:1327} INFO - Marking task as FAILED. dag_id=youtube_comments_score, task_id=get_data, execution_date=20230123T000500, start_date=20240123T180057, end_date=20240123T180059
[2024-01-24T02:00:59.223+0800] {standard_task_runner.py:100} ERROR - Failed to execute job 5 for task get_data (Bash command failed. The command returned a non-zero exit code 1.; 29467)
[2024-01-24T02:00:59.254+0800] {local_task_job.py:212} INFO - Task exited with return code 1
[2024-01-24T02:00:59.402+0800] {taskinstance.py:2596} INFO - 0 downstream tasks scheduled from follow-on schedule check
